Workbook

Sheet 📈 MASTER DASHBOARD
B2: BÁO CÁO TOÀN DIỆN CHẤM CÔNG CÁ NHÂN (12 THÁNG)
B3: TỔNG TIỀN CÔNG (TWD) | E3: TỔNG ĐÃ ỨNG (TWD) | I3: CÒN LẠI / THỰC LÃNH (TWD)
B4: ='⚙️ Calculation'!B1 -> 18200 | E4: ='⚙️ Calculation'!B2 -> 0 | I4: ='⚙️ Calculation'!B3 -> 18200

Sheet ⚙️ Calculation
A1: Tổng tiền làm ra | B1: =SUM(M2:M13) -> 18200 | D1: Dòng tiền | E1: Giá trị | H1: Tháng | I1: Thực Lãnh | J1: Đã Ứng | K1: Số Công O | L1: Số Công N | M1: Số Tiền Công Tổng | N1: Số Công X
A2: Tổng tiền đã ứng | B2: =SUM(J2:J13) -> 0 | D2: Thực lãnh | E2: =B3 -> 18200 | H2: T1 | I2: ='Tháng 1'!G52 -> 0 | J2: ='Tháng 1'!F52 -> 0 | K2: ='Tháng 1'!C52 -> 0 | L2: ='Tháng 1'!C53 -> 0 | M2: ='Tháng 1'!E52 -> 0 | N2: ='Tháng 1'!C54 -> 0
A3: Tổng thực lãnh | B3: =SUM(I2:I13) -> 18200 | D3: Đã ứng | E3: =B2 -> 0 | H3: T2 | I3: ='Tháng 2'!G52 -> 0 | J3: ='Tháng 2'!F52 -> 0 | K3: ='Tháng 2'!C52 -> 0 | L3: ='Tháng 2'!C53 -> 0 | M3: ='Tháng 2'!E52 -> 0 | N3: ='Tháng 2'!C54 -> 0
H4: T3 | I4: ='Tháng 3'!G52 -> 0 | J4: ='Tháng 3'!F52 -> 0 | K4: ='Tháng 3'!C52 -> 0 | L4: ='Tháng 3'!C53 -> 0 | M4: ='Tháng 3'!E52 -> 0 | N4: ='Tháng 3'!C54 -> 0
H5: T4 | I5: ='Tháng 4'!G52 -> 18200 | J5: ='Tháng 4'!F52 -> 0 | K5: ='Tháng 4'!C52 -> 6 | L5: ='Tháng 4'!C53 -> 1 | M5: ='Tháng 4'!E52 -> 18200 | N5: ='Tháng 4'!C54 -> 2
D6: Loại công | E6: Số lượng | H6: T5 | I6: ='Tháng 5'!G52 -> 0 | J6: ='Tháng 5'!F52 -> 0 | K6: ='Tháng 5'!C52 -> 0 | L6: ='Tháng 5'!C53 -> 0 | M6: ='Tháng 5'!E52 -> 0 | N6: ='Tháng 5'!C54 -> 0
D7: Cả ngày (O) | E7: =SUM(K2:K13) -> 6 | H7: T6 | I7: ='Tháng 6'!G52 -> 0 | J7: ='Tháng 6'!F52 -> 0 | K7: ='Tháng 6'!C52 -> 0 | L7: ='Tháng 6'!C53 -> 0 | M7: ='Tháng 6'!E52 -> 0 | N7: ='Tháng 6'!C54 -> 0
D8: Nửa ngày (N) | E8: =SUM(L2:L13) -> 1 | H8: T7 | I8: ='Tháng 7'!G52 -> 0 | J8: ='Tháng 7'!F52 -> 0 | K8: ='Tháng 7'!C52 -> 0 | L8: ='Tháng 7'!C53 -> 0 | M8: ='Tháng 7'!E52 -> 0 | N8: ='Tháng 7'!C54 -> 0
D9: Nghỉ (X) | E9: =SUM(N2:N13) -> 2 | H9: T8 | I9: ='Tháng 8'!G52 -> 0 | J9: ='Tháng 8'!F52 -> 0 | K9: ='Tháng 8'!C52 -> 0 | L9: ='Tháng 8'!C53 -> 0 | M9: ='Tháng 8'!E52 -> 0 | N9: ='Tháng 8'!C54 -> 0
H10: T9 | I10: ='Tháng 9'!G52 -> 0 | J10: ='Tháng 9'!F52 -> 0 | K10: ='Tháng 9'!C52 -> 0 | L10: ='Tháng 9'!C53 -> 0 | M10: ='Tháng 9'!E52 -> 0 | N10: ='Tháng 9'!C54 -> 0
H11: T10 | I11: ='Tháng 10'!G52 -> 0 | J11: ='Tháng 10'!F52 -> 0 | K11: ='Tháng 10'!C52 -> 0 | L11: ='Tháng 10'!C53 -> 0 | M11: ='Tháng 10'!E52 -> 0 | N11: ='Tháng 10'!C54 -> 0
H12: T11 | I12: ='Tháng 11'!G52 -> 0 | J12: ='Tháng 11'!F52 -> 0 | K12: ='Tháng 11'!C52 -> 0 | L12: ='Tháng 11'!C53 -> 0 | M12: ='Tháng 11'!E52 -> 0 | N12: ='Tháng 11'!C54 -> 0
H13: T12 | I13: ='Tháng 12'!G52 -> 0 | J13: ='Tháng 12'!F52 -> 0 | K13: ='Tháng 12'!C52 -> 0 | L13: ='Tháng 12'!C53 -> 0 | M13: ='Tháng 12'!E52 -> 0 | N13: ='Tháng 12'!C54 -> 0

Sheet Tháng 1
A1: Ngày | B1: Chủ (Chỗ làm) | C1: Công (O=1, N=0.5, X=0) | D1: Đơn giá (TWD) | E1: Tiền công (TWD) | F1: Đã ứng (TWD) | G1: THỰC LÃNH (TWD)
E2: =IF(C2="O",1,IF(C2="N",0.5,0))*D2 -> 0 | G2: =IF(E2=0,0,E2-F2) -> 0
E3: =IF(C3="O",1,IF(C3="N",0.5,0))*D3 -> 0 | G3: =IF(E3=0,0,E3-F3) -> 0
E4: =IF(C4="O",1,IF(C4="N",0.5,0))*D4 -> 0 | G4: =IF(E4=0,0,E4-F4) -> 0
E5: =IF(C5="O",1,IF(C5="N",0.5,0))*D5 -> 0 | G5: =IF(E5=0,0,E5-F5) -> 0
E6: =IF(C6="O",1,IF(C6="N",0.5,0))*D6 -> 0 | G6: =IF(E6=0,0,E6-F6) -> 0
E7: =IF(C7="O",1,IF(C7="N",0.5,0))*D7 -> 0 | G7: =IF(E7=0,0,E7-F7) -> 0
E8: =IF(C8="O",1,IF(C8="N",0.5,0))*D8 -> 0 | G8: =IF(E8=0,0,E8-F8) -> 0
E9: =IF(C9="O",1,IF(C9="N",0.5,0))*D9 -> 0 | G9: =IF(E9=0,0,E9-F9) -> 0
E10: =IF(C10="O",1,IF(C10="N",0.5,0))*D10 -> 0 | G10: =IF(E10=0,0,E10-F10) -> 0
E11: =IF(C11="O",1,IF(C11="N",0.5,0))*D11 -> 0 | G11: =IF(E11=0,0,E11-F11) -> 0
E12: =IF(C12="O",1,IF(C12="N",0.5,0))*D12 -> 0 | G12: =IF(E12=0,0,E12-F12) -> 0
E13: =IF(C13="O",1,IF(C13="N",0.5,0))*D13 -> 0 | G13: =IF(E13=0,0,E13-F13) -> 0
... E51: =IF(C51="O",1,IF(C51="N",0.5,0))*D51 -> 0 | G51: =IF(E51=0,0,E51-F51) -> 0
A52: TỔNG THÁNG 1 | C52: =COUNTIF(C2:C51,"O") -> 0 | E52: =SUM(E2:E51) -> 0 | F52: =SUM(F2:F51) -> 0 | G52: =SUM(G2:G51) -> 0
C53: =COUNTIF(C2:C51,"N") -> 0
C54: =COUNTIF(C2:C51,"X") -> 0

Sheet Tháng 2
A1: Ngày | B1: Chủ (Chỗ làm) | C1: Công (O=1, N=0.5, X=0) | D1: Đơn giá (TWD) | E1: Tiền công (TWD) | F1: Đã ứng (TWD) | G1: THỰC LÃNH (TWD)
E2: =IF(C2="O",1,IF(C2="N",0.5,0))*D2 -> 0 | G2: =IF(E2=0,0,E2-F2) -> 0
E3: =IF(C3="O",1,IF(C3="N",0.5,0))*D3 -> 0 | G3: =IF(E3=0,0,E3-F3) -> 0
E4: =IF(C4="O",1,IF(C4="N",0.5,0))*D4 -> 0 | G4: =IF(E4=0,0,E4-F4) -> 0
E5: =IF(C5="O",1,IF(C5="N",0.5,0))*D5 -> 0 | G5: =IF(E5=0,0,E5-F5) -> 0
E6: =IF(C6="O",1,IF(C6="N",0.5,0))*D6 -> 0 | G6: =IF(E6=0,0,E6-F6) -> 0
E7: =IF(C7="O",1,IF(C7="N",0.5,0))*D7 -> 0 | G7: =IF(E7=0,0,E7-F7) -> 0
E8: =IF(C8="O",1,IF(C8="N",0.5,0))*D8 -> 0 | G8: =IF(E8=0,0,E8-F8) -> 0
E9: =IF(C9="O",1,IF(C9="N",0.5,0))*D9 -> 0 | G9: =IF(E9=0,0,E9-F9) -> 0
E10: =IF(C10="O",1,IF(C10="N",0.5,0))*D10 -> 0 | G10: =IF(E10=0,0,E10-F10) -> 0
E11: =IF(C11="O",1,IF(C11="N",0.5,0))*D11 -> 0 | G11: =IF(E11=0,0,E11-F11) -> 0
E12: =IF(C12="O",1,IF(C12="N",0.5,0))*D12 -> 0 | G12: =IF(E12=0,0,E12-F12) -> 0
E13: =IF(C13="O",1,IF(C13="N",0.5,0))*D13 -> 0 | G13: =IF(E13=0,0,E13-F13) -> 0
... E51: =IF(C51="O",1,IF(C51="N",0.5,0))*D51 -> 0 | G51: =IF(E51=0,0,E51-F51) -> 0
A52: TỔNG THÁNG 2 | C52: =COUNTIF(C2:C51,"O") -> 0 | E52: =SUM(E2:E51) -> 0 | F52: =SUM(F2:F51) -> 0 | G52: =SUM(G2:G51) -> 0
C53: =COUNTIF(C2:C51,"N") -> 0
C54: =COUNTIF(C2:C51,"X") -> 0

Sheet Tháng 3
A1: Ngày | B1: Chủ (Chỗ làm) | C1: Công (O=1, N=0.5, X=0) | D1: Đơn giá (TWD) | E1: Tiền công (TWD) | F1: Đã ứng (TWD) | G1: THỰC LÃNH (TWD)
E2: =IF(C2="O",1,IF(C2="N",0.5,0))*D2 -> 0 | G2: =IF(E2=0,0,E2-F2) -> 0
E3: =IF(C3="O",1,IF(C3="N",0.5,0))*D3 -> 0 | G3: =IF(E3=0,0,E3-F3) -> 0
E4: =IF(C4="O",1,IF(C4="N",0.5,0))*D4 -> 0 | G4: =IF(E4=0,0,E4-F4) -> 0
E5: =IF(C5="O",1,IF(C5="N",0.5,0))*D5 -> 0 | G5: =IF(E5=0,0,E5-F5) -> 0
E6: =IF(C6="O",1,IF(C6="N",0.5,0))*D6 -> 0 | G6: =IF(E6=0,0,E6-F6) -> 0
E7: =IF(C7="O",1,IF(C7="N",0.5,0))*D7 -> 0 | G7: =IF(E7=0,0,E7-F7) -> 0
E8: =IF(C8="O",1,IF(C8="N",0.5,0))*D8 -> 0 | G8: =IF(E8=0,0,E8-F8) -> 0
E9: =IF(C9="O",1,IF(C9="N",0.5,0))*D9 -> 0 | G9: =IF(E9=0,0,E9-F9) -> 0
E10: =IF(C10="O",1,IF(C10="N",0.5,0))*D10 -> 0 | G10: =IF(E10=0,0,E10-F10) -> 0
E11: =IF(C11="O",1,IF(C11="N",0.5,0))*D11 -> 0 | G11: =IF(E11=0,0,E11-F11) -> 0
E12: =IF(C12="O",1,IF(C12="N",0.5,0))*D12 -> 0 | G12: =IF(E12=0,0,E12-F12) -> 0
E13: =IF(C13="O",1,IF(C13="N",0.5,0))*D13 -> 0 | G13: =IF(E13=0,0,E13-F13) -> 0
... E51: =IF(C51="O",1,IF(C51="N",0.5,0))*D51 -> 0 | G51: =IF(E51=0,0,E51-F51) -> 0
A52: TỔNG THÁNG 3 | C52: =COUNTIF(C2:C51,"O") -> 0 | E52: =SUM(E2:E51) -> 0 | F52: =SUM(F2:F51) -> 0 | G52: =SUM(G2:G51) -> 0
C53: =COUNTIF(C2:C51,"N") -> 0
C54: =COUNTIF(C2:C51,"X") -> 0

Sheet Tháng 4
A1: Ngày | B1: Chủ (Chỗ làm) | C1: Công (O=1, N=0.5, X=0) | D1: Đơn giá (TWD) | E1: Tiền công (TWD) | F1: Đã ứng (TWD) | G1: THỰC LÃNH (TWD)
A2: 46113 | E2: =IF(C2="O",1,IF(C2="N",0.5,0))*D2 -> 0 | G2: =IF(E2=0,0,E2-F2) -> 0
A3: 46114 | E3: =IF(C3="O",1,IF(C3="N",0.5,0))*D3 -> 0 | G3: =IF(E3=0,0,E3-F3) -> 0
A4: 46115 | B4: DŨNG LUKANG | C4: O | D4: 2800 | E4: =IF(C4="O",1,IF(C4="N",0.5,0))*D4 -> 2800 | G4: =IF(E4=0,0,E4-F4) -> 2800
A5: 46116 | B5: DŨNG LUKANG | C5: X | D5: 2800 | E5: =IF(C5="O",1,IF(C5="N",0.5,0))*D5 -> 0 | G5: =IF(E5=0,0,E5-F5) -> 0
A6: 46117 | B6: DŨNG LUKANG | C6: X | D6: 2800 | E6: =IF(C6="O",1,IF(C6="N",0.5,0))*D6 -> 0 | G6: =IF(E6=0,0,E6-F6) -> 0
A7: 46118 | B7: DŨNG LUKANG | C7: O | D7: 2800 | E7: =IF(C7="O",1,IF(C7="N",0.5,0))*D7 -> 2800 | G7: =IF(E7=0,0,E7-F7) -> 2800
A8: 46119 | B8: DŨNG LUKANG | C8: O | D8: 2800 | E8: =IF(C8="O",1,IF(C8="N",0.5,0))*D8 -> 2800 | G8: =IF(E8=0,0,E8-F8) -> 2800
A9: 46120 | B9: DŨNG LUKANG | C9: O | D9: 2800 | E9: =IF(C9="O",1,IF(C9="N",0.5,0))*D9 -> 2800 | G9: =IF(E9=0,0,E9-F9) -> 2800
A10: 46121 | B10: DŨNG HEMEI | C10: O | D10: 2800 | E10: =IF(C10="O",1,IF(C10="N",0.5,0))*D10 -> 2800 | G10: =IF(E10=0,0,E10-F10) -> 2800
A11: 46122 | B11: DŨNG LUKANG | C11: O | D11: 2800 | E11: =IF(C11="O",1,IF(C11="N",0.5,0))*D11 -> 2800 | G11: =IF(E11=0,0,E11-F11) -> 2800
A12: 46123 | B12: DŨNG LUKANG | C12: N | D12: 2800 | E12: =IF(C12="O",1,IF(C12="N",0.5,0))*D12 -> 1400 | G12: =IF(E12=0,0,E12-F12) -> 1400
A13: 46124 | E13: =IF(C13="O",1,IF(C13="N",0.5,0))*D13 -> 0 | G13: =IF(E13=0,0,E13-F13) -> 0
A14: 46125 | E14: =IF(C14="O",1,IF(C14="N",0.5,0))*D14 -> 0 | G14: =IF(E14=0,0,E14-F14) -> 0
A15: 46126 | E15: =IF(C15="O",1,IF(C15="N",0.5,0))*D15 -> 0 | G15: =IF(E15=0,0,E15-F15) -> 0
A16: 46127 | E16: =IF(C16="O",1,IF(C16="N",0.5,0))*D16 -> 0 | G16: =IF(E16=0,0,E16-F16) -> 0
A17: 46128 | E17: =IF(C17="O",1,IF(C17="N",0.5,0))*D17 -> 0 | G17: =IF(E17=0,0,E17-F17) -> 0
A18: 46129 | E18: =IF(C18="O",1,IF(C18="N",0.5,0))*D18 -> 0 | G18: =IF(E18=0,0,E18-F18) -> 0
A19: 46130 | E19: =IF(C19="O",1,IF(C19="N",0.5,0))*D19 -> 0 | G19: =IF(E19=0,0,E19-F19) -> 0
A20: 46131 | E20: =IF(C20="O",1,IF(C20="N",0.5,0))*D20 -> 0 | G20: =IF(E20=0,0,E20-F20) -> 0
A21: 46132 | E21: =IF(C21="O",1,IF(C21="N",0.5,0))*D21 -> 0 | G21: =IF(E21=0,0,E21-F21) -> 0
A22: 46133 | E22: =IF(C22="O",1,IF(C22="N",0.5,0))*D22 -> 0 | G22: =IF(E22=0,0,E22-F22) -> 0
A23: 46134 | E23: =IF(C23="O",1,IF(C23="N",0.5,0))*D23 -> 0 | G23: =IF(E23=0,0,E23-F23) -> 0
A24: 46135 | E24: =IF(C24="O",1,IF(C24="N",0.5,0))*D24 -> 0 | G24: =IF(E24=0,0,E24-F24) -> 0
... A31: 46142 | E31: =IF(C31="O",1,IF(C31="N",0.5,0))*D31 -> 0 | G31: =IF(E31=0,0,E31-F31) -> 0
E32: =IF(C32="O",1,IF(C32="N",0.5,0))*D32 -> 0 | G32: =IF(E32=0,0,E32-F32) -> 0
E33: =IF(C33="O",1,IF(C33="N",0.5,0))*D33 -> 0 | G33: =IF(E33=0,0,E33-F33) -> 0
E34: =IF(C34="O",1,IF(C34="N",0.5,0))*D34 -> 0 | G34: =IF(E34=0,0,E34-F34) -> 0
E35: =IF(C35="O",1,IF(C35="N",0.5,0))*D35 -> 0 | G35: =IF(E35=0,0,E35-F35) -> 0
E36: =IF(C36="O",1,IF(C36="N",0.5,0))*D36 -> 0 | G36: =IF(E36=0,0,E36-F36) -> 0
E37: =IF(C37="O",1,IF(C37="N",0.5,0))*D37 -> 0 | G37: =IF(E37=0,0,E37-F37) -> 0
E38: =IF(C38="O",1,IF(C38="N",0.5,0))*D38 -> 0 | G38: =IF(E38=0,0,E38-F38) -> 0
E39: =IF(C39="O",1,IF(C39="N",0.5,0))*D39 -> 0 | G39: =IF(E39=0,0,E39-F39) -> 0
E40: =IF(C40="O",1,IF(C40="N",0.5,0))*D40 -> 0 | G40: =IF(E40=0,0,E40-F40) -> 0
E41: =IF(C41="O",1,IF(C41="N",0.5,0))*D41 -> 0 | G41: =IF(E41=0,0,E41-F41) -> 0
E42: =IF(C42="O",1,IF(C42="N",0.5,0))*D42 -> 0 | G42: =IF(E42=0,0,E42-F42) -> 0
E43: =IF(C43="O",1,IF(C43="N",0.5,0))*D43 -> 0 | G43: =IF(E43=0,0,E43-F43) -> 0
... E51: =IF(C51="O",1,IF(C51="N",0.5,0))*D51 -> 0 | G51: =IF(E51=0,0,E51-F51) -> 0
A52: TỔNG THÁNG 4 | C52: =COUNTIF(C2:C51,"O") -> 6 | E52: =SUM(E2:E51) -> 18200 | F52: =SUM(F2:F51) -> 0 | G52: =SUM(G2:G51) -> 18200
C53: =COUNTIF(C2:C51,"N") -> 1
...

Sheet Tháng 5
A1: Ngày | B1: Chủ (Chỗ làm) | C1: Công (O=1, N=0.5, X=0) | D1: Đơn giá (TWD) | E1: Tiền công (TWD) | F1: Đã ứng (TWD) | G1: THỰC LÃNH (TWD)
E2: =IF(C2="O",1,IF(C2="N",0.5,0))*D2 -> 0 | G2: =IF(E2=0,0,E2-F2) -> 0
E3: =IF(C3="O",1,IF(C3="N",0.5,0))*D3 -> 0 | G3: =IF(E3=0,0,E3-F3) -> 0
E4: =IF(C4="O",1,IF(C4="N",0.5,0))*D4 -> 0 | G4: =IF(E4=0,0,E4-F4) -> 0
E5: =IF(C5="O",1,IF(C5="N",0.5,0))*D5 -> 0 | G5: =IF(E5=0,0,E5-F5) -> 0
E6: =IF(C6="O",1,IF(C6="N",0.5,0))*D6 -> 0 | G6: =IF(E6=0,0,E6-F6) -> 0
E7: =IF(C7="O",1,IF(C7="N",0.5,0))*D7 -> 0 | G7: =IF(E7=0,0,E7-F7) -> 0
E8: =IF(C8="O",1,IF(C8="N",0.5,0))*D8 -> 0 | G8: =IF(E8=0,0,E8-F8) -> 0
E9: =IF(C9="O",1,IF(C9="N",0.5,0))*D9 -> 0 | G9: =IF(E9=0,0,E9-F9) -> 0
E10: =IF(C10="O",1,IF(C10="N",0.5,0))*D10 -> 0 | G10: =IF(E10=0,0,E10-F10) -> 0
E11: =IF(C11="O",1,IF(C11="N",0.5,0))*D11 -> 0 | G11: =IF(E11=0,0,E11-F11) -> 0
E12: =IF(C12="O",1,IF(C12="N",0.5,0))*D12 -> 0 | G12: =IF(E12=0,0,E12-F12) -> 0
E13: =IF(C13="O",1,IF(C13="N",0.5,0))*D13 -> 0 | G13: =IF(E13=0,0,E13-F13) -> 0
... E51: =IF(C51="O",1,IF(C51="N",0.5,0))*D51 -> 0 | G51: =IF(E51=0,0,E51-F51) -> 0
A52: TỔNG THÁNG 5 | C52: =COUNTIF(C2:C51,"O") -> 0 | E52: =SUM(E2:E51) -> 0 | F52: =SUM(F2:F51) -> 0 | G52: =SUM(G2:G51) -> 0
C53: =COUNTIF(C2:C51,"N") -> 0
C54: =COUNTIF(C2:C51,"X") -> 0

Sheet Tháng 6
A1: Ngày | B1: Chủ (Chỗ làm) | C1: Công (O=1, N=0.5, X=0) | D1: Đơn giá (TWD) | E1: Tiền công (TWD) | F1: Đã ứng (TWD) | G1: THỰC LÃNH (TWD)
E2: =IF(C2="O",1,IF(C2="N",0.5,0))*D2 -> 0 | G2: =IF(E2=0,0,E2-F2) -> 0
E3: =IF(C3="O",1,IF(C3="N",0.5,0))*D3 -> 0 | G3: =IF(E3=0,0,E3-F3) -> 0
E4: =IF(C4="O",1,IF(C4="N",0.5,0))*D4 -> 0 | G4: =IF(E4=0,0,E4-F4) -> 0
E5: =IF(C5="O",1,IF(C5="N",0.5,0))*D5 -> 0 | G5: =IF(E5=0,0,E5-F5) -> 0
E6: =IF(C6="O",1,IF(C6="N",0.5,0))*D6 -> 0 | G6: =IF(E6=0,0,E6-F6) -> 0
E7: =IF(C7="O",1,IF(C7="N",0.5,0))*D7 -> 0 | G7: =IF(E7=0,0,E7-F7) -> 0
E8: =IF(C8="O",1,IF(C8="N",0.5,0))*D8 -> 0 | G8: =IF(E8=0,0,E8-F8) -> 0
E9: =IF(C9="O",1,IF(C9="N",0.5,0))*D9 -> 0 | G9: =IF(E9=0,0,E9-F9) -> 0
E10: =IF(C10="O",1,IF(C10="N",0.5,0))*D10 -> 0 | G10: =IF(E10=0,0,E10-F10) -> 0
E11: =IF(C11="O",1,IF(C11="N",0.5,0))*D11 -> 0 | G11: =IF(E11=0,0,E11-F11) -> 0
E12: =IF(C12="O",1,IF(C12="N",0.5,0))*D12 -> 0 | G12: =IF(E12=0,0,E12-F12) -> 0
E13: =IF(C13="O",1,IF(C13="N",0.5,0))*D13 -> 0 | G13: =IF(E13=0,0,E13-F13) -> 0
... E51: =IF(C51="O",1,IF(C51="N",0.5,0))*D51 -> 0 | G51: =IF(E51=0,0,E51-F51) -> 0
A52: TỔNG THÁNG 6 | C52: =COUNTIF(C2:C51,"O") -> 0 | E52: =SUM(E2:E51) -> 0 | F52: =SUM(F2:F51) -> 0 | G52: =SUM(G2:G51) -> 0
C53: =COUNTIF(C2:C51,"N") -> 0
C54: =COUNTIF(C2:C51,"X") -> 0

Sheet Tháng 7
A1: Ngày | B1: Chủ (Chỗ làm) | C1: Công (O=1, N=0.5, X=0) | D1: Đơn giá (TWD) | E1: Tiền công (TWD) | F1: Đã ứng (TWD) | G1: THỰC LÃNH (TWD)
E2: =IF(C2="O",1,IF(C2="N",0.5,0))*D2 -> 0 | G2: =IF(E2=0,0,E2-F2) -> 0
E3: =IF(C3="O",1,IF(C3="N",0.5,0))*D3 -> 0 | G3: =IF(E3=0,0,E3-F3) -> 0
E4: =IF(C4="O",1,IF(C4="N",0.5,0))*D4 -> 0 | G4: =IF(E4=0,0,E4-F4) -> 0
E5: =IF(C5="O",1,IF(C5="N",0.5,0))*D5 -> 0 | G5: =IF(E5=0,0,E5-F5) -> 0
E6: =IF(C6="O",1,IF(C6="N",0.5,0))*D6 -> 0 | G6: =IF(E6=0,0,E6-F6) -> 0
E7: =IF(C7="O",1,IF(C7="N",0.5,0))*D7 -> 0 | G7: =IF(E7=0,0,E7-F7) -> 0
E8: =IF(C8="O",1,IF(C8="N",0.5,0))*D8 -> 0 | G8: =IF(E8=0,0,E8-F8) -> 0
E9: =IF(C9="O",1,IF(C9="N",0.5,0))*D9 -> 0 | G9: =IF(E9=0,0,E9-F9) -> 0
E10: =IF(C10="O",1,IF(C10="N",0.5,0))*D10 -> 0 | G10: =IF(E10=0,0,E10-F10) -> 0
E11: =IF(C11="O",1,IF(C11="N",0.5,0))*D11 -> 0 | G11: =IF(E11=0,0,E11-F11) -> 0
E12: =IF(C12="O",1,IF(C12="N",0.5,0))*D12 -> 0 | G12: =IF(E12=0,0,E12-F12) -> 0
E13: =IF(C13="O",1,IF(C13="N",0.5,0))*D13 -> 0 | G13: =IF(E13=0,0,E13-F13) -> 0
... E51: =IF(C51="O",1,IF(C51="N",0.5,0))*D51 -> 0 | G51: =IF(E51=0,0,E51-F51) -> 0
A52: TỔNG THÁNG 7 | C52: =COUNTIF(C2:C51,"O") -> 0 | E52: =SUM(E2:E51) -> 0 | F52: =SUM(F2:F51) -> 0 | G52: =SUM(G2:G51) -> 0
C53: =COUNTIF(C2:C51,"N") -> 0
C54: =COUNTIF(C2:C51,"X") -> 0

Sheet Tháng 8
A1: Ngày | B1: Chủ (Chỗ làm) | C1: Công (O=1, N=0.5, X=0) | D1: Đơn giá (TWD) | E1: Tiền công (TWD) | F1: Đã ứng (TWD) | G1: THỰC LÃNH (TWD)
E2: =IF(C2="O",1,IF(C2="N",0.5,0))*D2 -> 0 | G2: =IF(E2=0,0,E2-F2) -> 0
E3: =IF(C3="O",1,IF(C3="N",0.5,0))*D3 -> 0 | G3: =IF(E3=0,0,E3-F3) -> 0
E4: =IF(C4="O",1,IF(C4="N",0.5,0))*D4 -> 0 | G4: =IF(E4=0,0,E4-F4) -> 0
E5: =IF(C5="O",1,IF(C5="N",0.5,0))*D5 -> 0 | G5: =IF(E5=0,0,E5-F5) -> 0
E6: =IF(C6="O",1,IF(C6="N",0.5,0))*D6 -> 0 | G6: =IF(E6=0,0,E6-F6) -> 0
E7: =IF(C7="O",1,IF(C7="N",0.5,0))*D7 -> 0 | G7: =IF(E7=0,0,E7-F7) -> 0
E8: =IF(C8="O",1,IF(C8="N",0.5,0))*D8 -> 0 | G8: =IF(E8=0,0,E8-F8) -> 0
E9: =IF(C9="O",1,IF(C9="N",0.5,0))*D9 -> 0 | G9: =IF(E9=0,0,E9-F9) -> 0
E10: =IF(C10="O",1,IF(C10="N",0.5,0))*D10 -> 0 | G10: =IF(E10=0,0,E10-F10) -> 0
E11: =IF(C11="O",1,IF(C11="N",0.5,0))*D11 -> 0 | G11: =IF(E11=0,0,E11-F11) -> 0
E12: =IF(C12="O",1,IF(C12="N",0.5,0))*D12 -> 0 | G12: =IF(E12=0,0,E12-F12) -> 0
E13: =IF(C13="O",1,IF(C13="N",0.5,0))*D13 -> 0 | G13: =IF(E13=0,0,E13-F13) -> 0
... E51: =IF(C51="O",1,IF(C51="N",0.5,0))*D51 -> 0 | G51: =IF(E51=0,0,E51-F51) -> 0
A52: TỔNG THÁNG 8 | C52: =COUNTIF(C2:C51,"O") -> 0 | E52: =SUM(E2:E51) -> 0 | F52: =SUM(F2:F51) -> 0 | G52: =SUM(G2:G51) -> 0
C53: =COUNTIF(C2:C51,"N") -> 0
C54: =COUNTIF(C2:C51,"X") -> 0

Sheet Tháng 9
A1: Ngày | B1: Chủ (Chỗ làm) | C1: Công (O=1, N=0.5, X=0) | D1: Đơn giá (TWD) | E1: Tiền công (TWD) | F1: Đã ứng (TWD) | G1: THỰC LÃNH (TWD)
E2: =IF(C2="O",1,IF(C2="N",0.5,0))*D2 -> 0 | G2: =IF(E2=0,0,E2-F2) -> 0
E3: =IF(C3="O",1,IF(C3="N",0.5,0))*D3 -> 0 | G3: =IF(E3=0,0,E3-F3) -> 0
E4: =IF(C4="O",1,IF(C4="N",0.5,0))*D4 -> 0 | G4: =IF(E4=0,0,E4-F4) -> 0
E5: =IF(C5="O",1,IF(C5="N",0.5,0))*D5 -> 0 | G5: =IF(E5=0,0,E5-F5) -> 0
E6: =IF(C6="O",1,IF(C6="N",0.5,0))*D6 -> 0 | G6: =IF(E6=0,0,E6-F6) -> 0
E7: =IF(C7="O",1,IF(C7="N",0.5,0))*D7 -> 0 | G7: =IF(E7=0,0,E7-F7) -> 0
E8: =IF(C8="O",1,IF(C8="N",0.5,0))*D8 -> 0 | G8: =IF(E8=0,0,E8-F8) -> 0
E9: =IF(C9="O",1,IF(C9="N",0.5,0))*D9 -> 0 | G9: =IF(E9=0,0,E9-F9) -> 0
E10: =IF(C10="O",1,IF(C10="N",0.5,0))*D10 -> 0 | G10: =IF(E10=0,0,E10-F10) -> 0
E11: =IF(C11="O",1,IF(C11="N",0.5,0))*D11 -> 0 | G11: =IF(E11=0,0,E11-F11) -> 0
E12: =IF(C12="O",1,IF(C12="N",0.5,0))*D12 -> 0 | G12: =IF(E12=0,0,E12-F12) -> 0
E13: =IF(C13="O",1,IF(C13="N",0.5,0))*D13 -> 0 | G13: =IF(E13=0,0,E13-F13) -> 0
... E51: =IF(C51="O",1,IF(C51="N",0.5,0))*D51 -> 0 | G51: =IF(E51=0,0,E51-F51) -> 0
A52: TỔNG THÁNG 9 | C52: =COUNTIF(C2:C51,"O") -> 0 | E52: =SUM(E2:E51) -> 0 | F52: =SUM(F2:F51) -> 0 | G52: =SUM(G2:G51) -> 0
C53: =COUNTIF(C2:C51,"N") -> 0
C54: =COUNTIF(C2:C51,"X") -> 0

Sheet Tháng 10
A1: Ngày | B1: Chủ (Chỗ làm) | C1: Công (O=1, N=0.5, X=0) | D1: Đơn giá (TWD) | E1: Tiền công (TWD) | F1: Đã ứng (TWD) | G1: THỰC LÃNH (TWD)
E2: =IF(C2="O",1,IF(C2="N",0.5,0))*D2 -> 0 | G2: =IF(E2=0,0,E2-F2) -> 0
E3: =IF(C3="O",1,IF(C3="N",0.5,0))*D3 -> 0 | G3: =IF(E3=0,0,E3-F3) -> 0
E4: =IF(C4="O",1,IF(C4="N",0.5,0))*D4 -> 0 | G4: =IF(E4=0,0,E4-F4) -> 0
E5: =IF(C5="O",1,IF(C5="N",0.5,0))*D5 -> 0 | G5: =IF(E5=0,0,E5-F5) -> 0
E6: =IF(C6="O",1,IF(C6="N",0.5,0))*D6 -> 0 | G6: =IF(E6=0,0,E6-F6) -> 0
E7: =IF(C7="O",1,IF(C7="N",0.5,0))*D7 -> 0 | G7: =IF(E7=0,0,E7-F7) -> 0
E8: =IF(C8="O",1,IF(C8="N",0.5,0))*D8 -> 0 | G8: =IF(E8=0,0,E8-F8) -> 0
E9: =IF(C9="O",1,IF(C9="N",0.5,0))*D9 -> 0 | G9: =IF(E9=0,0,E9-F9) -> 0
E10: =IF(C10="O",1,IF(C10="N",0.5,0))*D10 -> 0 | G10: =IF(E10=0,0,E10-F10) -> 0
E11: =IF(C11="O",1,IF(C11="N",0.5,0))*D11 -> 0 | G11: =IF(E11=0,0,E11-F11) -> 0
E12: =IF(C12="O",1,IF(C12="N",0.5,0))*D12 -> 0 | G12: =IF(E12=0,0,E12-F12) -> 0
E13: =IF(C13="O",1,IF(C13="N",0.5,0))*D13 -> 0 | G13: =IF(E13=0,0,E13-F13) -> 0
... E51: =IF(C51="O",1,IF(C51="N",0.5,0))*D51 -> 0 | G51: =IF(E51=0,0,E51-F51) -> 0
A52: TỔNG THÁNG 10 | C52: =COUNTIF(C2:C51,"O") -> 0 | E52: =SUM(E2:E51) -> 0 | F52: =SUM(F2:F51) -> 0 | G52: =SUM(G2:G51) -> 0
C53: =COUNTIF(C2:C51,"N") -> 0
C54: =COUNTIF(C2:C51,"X") -> 0

Sheet Tháng 11
A1: Ngày | B1: Chủ (Chỗ làm) | C1: Công (O=1, N=0.5, X=0) | D1: Đơn giá (TWD) | E1: Tiền công (TWD) | F1: Đã ứng (TWD) | G1: THỰC LÃNH (TWD)
E2: =IF(C2="O",1,IF(C2="N",0.5,0))*D2 -> 0 | G2: =IF(E2=0,0,E2-F2) -> 0
E3: =IF(C3="O",1,IF(C3="N",0.5,0))*D3 -> 0 | G3: =IF(E3=0,0,E3-F3) -> 0
E4: =IF(C4="O",1,IF(C4="N",0.5,0))*D4 -> 0 | G4: =IF(E4=0,0,E4-F4) -> 0
E5: =IF(C5="O",1,IF(C5="N",0.5,0))*D5 -> 0 | G5: =IF(E5=0,0,E5-F5) -> 0
E6: =IF(C6="O",1,IF(C6="N",0.5,0))*D6 -> 0 | G6: =IF(E6=0,0,E6-F6) -> 0
E7: =IF(C7="O",1,IF(C7="N",0.5,0))*D7 -> 0 | G7: =IF(E7=0,0,E7-F7) -> 0
E8: =IF(C8="O",1,IF(C8="N",0.5,0))*D8 -> 0 | G8: =IF(E8=0,0,E8-F8) -> 0
E9: =IF(C9="O",1,IF(C9="N",0.5,0))*D9 -> 0 | G9: =IF(E9=0,0,E9-F9) -> 0
E10: =IF(C10="O",1,IF(C10="N",0.5,0))*D10 -> 0 | G10: =IF(E10=0,0,E10-F10) -> 0
E11: =IF(C11="O",1,IF(C11="N",0.5,0))*D11 -> 0 | G11: =IF(E11=0,0,E11-F11) -> 0
E12: =IF(C12="O",1,IF(C12="N",0.5,0))*D12 -> 0 | G12: =IF(E12=0,0,E12-F12) -> 0
E13: =IF(C13="O",1,IF(C13="N",0.5,0))*D13 -> 0 | G13: =IF(E13=0,0,E13-F13) -> 0
... E51: =IF(C51="O",1,IF(C51="N",0.5,0))*D51 -> 0 | G51: =IF(E51=0,0,E51-F51) -> 0
A52: TỔNG THÁNG 11 | C52: =COUNTIF(C2:C51,"O") -> 0 | E52: =SUM(E2:E51) -> 0 | F52: =SUM(F2:F51) -> 0 | G52: =SUM(G2:G51) -> 0
C53: =COUNTIF(C2:C51,"N") -> 0
C54: =COUNTIF(C2:C51,"X") -> 0

Sheet Tháng 12
A1: Ngày | B1: Chủ (Chỗ làm) | C1: Công (O=1, N=0.5, X=0) | D1: Đơn giá (TWD) | E1: Tiền công (TWD) | F1: Đã ứng (TWD) | G1: THỰC LÃNH (TWD)
E2: =IF(C2="O",1,IF(C2="N",0.5,0))*D2 -> 0 | G2: =IF(E2=0,0,E2-F2) -> 0
E3: =IF(C3="O",1,IF(C3="N",0.5,0))*D3 -> 0 | G3: =IF(E3=0,0,E3-F3) -> 0
E4: =IF(C4="O",1,IF(C4="N",0.5,0))*D4 -> 0 | G4: =IF(E4=0,0,E4-F4) -> 0
E5: =IF(C5="O",1,IF(C5="N",0.5,0))*D5 -> 0 | G5: =IF(E5=0,0,E5-F5) -> 0
E6: =IF(C6="O",1,IF(C6="N",0.5,0))*D6 -> 0 | G6: =IF(E6=0,0,E6-F6) -> 0
E7: =IF(C7="O",1,IF(C7="N",0.5,0))*D7 -> 0 | G7: =IF(E7=0,0,E7-F7) -> 0
E8: =IF(C8="O",1,IF(C8="N",0.5,0))*D8 -> 0 | G8: =IF(E8=0,0,E8-F8) -> 0
E9: =IF(C9="O",1,IF(C9="N",0.5,0))*D9 -> 0 | G9: =IF(E9=0,0,E9-F9) -> 0
E10: =IF(C10="O",1,IF(C10="N",0.5,0))*D10 -> 0 | G10: =IF(E10=0,0,E10-F10) -> 0
E11: =IF(C11="O",1,IF(C11="N",0.5,0))*D11 -> 0 | G11: =IF(E11=0,0,E11-F11) -> 0
E12: =IF(C12="O",1,IF(C12="N",0.5,0))*D12 -> 0 | G12: =IF(E12=0,0,E12-F12) -> 0
E13: =IF(C13="O",1,IF(C13="N",0.5,0))*D13 -> 0 | G13: =IF(E13=0,0,E13-F13) -> 0
... E51: =IF(C51="O",1,IF(C51="N",0.5,0))*D51 -> 0 | G51: =IF(E51=0,0,E51-F51) -> 0
A52: TỔNG THÁNG 12 | C52: =COUNTIF(C2:C51,"O") -> 0 | E52: =SUM(E2:E51) -> 0 | F52: =SUM(F2:F51) -> 0 | G52: =SUM(G2:G51) -> 0
C53: =COUNTIF(C2:C51,"N") -> 0
C54: =COUNTIF(C2:C51,"X") -> 0
